Traceback (most recent call last):
  File "H:\HadiSadoghiYazdi\Circuit\Lib\site-packages\jupyter_cache\executors\utils.py", line 58, in single_nb_execution
    executenb(
    ~~~~~~~~~^
        nb,
        ^^^
    ...<4 lines>...
        **kwargs,
        ^^^^^^^^^
    )
    ^
  File "H:\HadiSadoghiYazdi\Circuit\Lib\site-packages\nbclient\client.py", line 1314, in execute
    return NotebookClient(nb=nb, resources=resources, km=km, **kwargs).execute()
           ~~~~~~~~~~~~~~~~~~~~~~~~~~~~~~~~~~~~~~~~~~~~~~~~~~~~~~~~~~~~~~~~~~~^^
  File "H:\HadiSadoghiYazdi\Circuit\Lib\site-packages\jupyter_core\utils\__init__.py", line 165, in wrapped
    return loop.run_until_complete(inner)
           ~~~~~~~~~~~~~~~~~~~~~~~^^^^^^^
  File "C:\Program Files\Python313\Lib\asyncio\base_events.py", line 721, in run_until_complete
    return future.result()
           ~~~~~~~~~~~~~^^
  File "H:\HadiSadoghiYazdi\Circuit\Lib\site-packages\nbclient\client.py", line 709, in async_execute
    await self.async_execute_cell(
        cell, index, execution_count=self.code_cells_executed + 1
    )
  File "H:\HadiSadoghiYazdi\Circuit\Lib\site-packages\nbclient\client.py", line 1062, in async_execute_cell
    await self._check_raise_for_error(cell, cell_index, exec_reply)
  File "H:\HadiSadoghiYazdi\Circuit\Lib\site-packages\nbclient\client.py", line 918, in _check_raise_for_error
    raise CellExecutionError.from_cell_and_msg(cell, exec_reply_content)
nbclient.exceptions.CellExecutionError: An error occurred while executing the following cell:
------------------
import matplotlib.pyplot as plt
import numpy as np
from sklearn.neighbors import NearestNeighbors
import matplotlib.cm as cm

data = np.random.rand(8, 2)

def kneighbors(n_neighbors, data):
    knn_model = NearestNeighbors(n_neighbors=n_neighbors+1, metric='l2')
    knn_model.fit(data)
    kindices = knn_model.kneighbors(data)[1][:, 1:]
    return kindices

n_neighbors = 3
neighbors_indices = kneighbors(n_neighbors, data)

colors = cm.rainbow(np.linspace(0, 1, data.shape[0]))

plt.scatter(data[:, 0], data[:, 1], color='black')

for i in range(data.shape[0]):
    for j in neighbors_indices[i]:
        plt.plot([data[i, 0], data[j, 0]], [data[i, 1], data[j, 1]], color=colors[i])

plt.title("Scatter plot with colored neighbor connections")
plt.xlabel("X-axis")
plt.ylabel("Y-axis")
plt.show()

------------------


[1;31m---------------------------------------------------------------------------[0m
[1;31mModuleNotFoundError[0m                       Traceback (most recent call last)
Cell [1;32mIn[1], line 3[0m
[0;32m      1[0m [38;5;28;01mimport[39;00m [38;5;21;01mmatplotlib[39;00m[38;5;21;01m.[39;00m[38;5;21;01mpyplot[39;00m [38;5;28;01mas[39;00m [38;5;21;01mplt[39;00m
[0;32m      2[0m [38;5;28;01mimport[39;00m [38;5;21;01mnumpy[39;00m [38;5;28;01mas[39;00m [38;5;21;01mnp[39;00m
[1;32m----> 3[0m [38;5;28;01mfrom[39;00m [38;5;21;01msklearn[39;00m[38;5;21;01m.[39;00m[38;5;21;01mneighbors[39;00m [38;5;28;01mimport[39;00m NearestNeighbors
[0;32m      4[0m [38;5;28;01mimport[39;00m [38;5;21;01mmatplotlib[39;00m[38;5;21;01m.[39;00m[38;5;21;01mcm[39;00m [38;5;28;01mas[39;00m [38;5;21;01mcm[39;00m
[0;32m      6[0m data [38;5;241m=[39m np[38;5;241m.[39mrandom[38;5;241m.[39mrand([38;5;241m8[39m, [38;5;241m2[39m)

[1;31mModuleNotFoundError[0m: No module named 'sklearn'

