Traceback (most recent call last):
  File "H:\HadiSadoghiYazdi\PL\Lib\site-packages\jupyter_cache\executors\utils.py", line 58, in single_nb_execution
    executenb(
    ~~~~~~~~~^
        nb,
        ^^^
    ...<4 lines>...
        **kwargs,
        ^^^^^^^^^
    )
    ^
  File "H:\HadiSadoghiYazdi\PL\Lib\site-packages\nbclient\client.py", line 1314, in execute
    return NotebookClient(nb=nb, resources=resources, km=km, **kwargs).execute()
           ~~~~~~~~~~~~~~~~~~~~~~~~~~~~~~~~~~~~~~~~~~~~~~~~~~~~~~~~~~~~~~~~~~~^^
  File "H:\HadiSadoghiYazdi\PL\Lib\site-packages\jupyter_core\utils\__init__.py", line 165, in wrapped
    return loop.run_until_complete(inner)
           ~~~~~~~~~~~~~~~~~~~~~~~^^^^^^^
  File "C:\Program Files\Python313\Lib\asyncio\base_events.py", line 721, in run_until_complete
    return future.result()
           ~~~~~~~~~~~~~^^
  File "H:\HadiSadoghiYazdi\PL\Lib\site-packages\nbclient\client.py", line 709, in async_execute
    await self.async_execute_cell(
        cell, index, execution_count=self.code_cells_executed + 1
    )
  File "H:\HadiSadoghiYazdi\PL\Lib\site-packages\nbclient\client.py", line 1062, in async_execute_cell
    await self._check_raise_for_error(cell, cell_index, exec_reply)
  File "H:\HadiSadoghiYazdi\PL\Lib\site-packages\nbclient\client.py", line 918, in _check_raise_for_error
    raise CellExecutionError.from_cell_and_msg(cell, exec_reply_content)
nbclient.exceptions.CellExecutionError: An error occurred while executing the following cell:
------------------

import numpy as np
import pandas as pd

import matplotlib.pyplot as plt

from sklearn.datasets import make_blobs
from sklearn.neighbors import KNeighborsClassifier
from sklearn.model_selection import train_test_split

X, y = make_blobs(n_samples = 500, n_features = 2, centers = 4,cluster_std = 1.5, random_state = 4)

plt.style.use('seaborn')
plt.figure(figsize = (10,10))
plt.scatter(X[:,0], X[:,1], c=y, marker= '*',s=100,edgecolors='black')
plt.show()
------------------


[1;31m---------------------------------------------------------------------------[0m
[1;31mFileNotFoundError[0m                         Traceback (most recent call last)
File [1;32mH:\HadiSadoghiYazdi\PL\Lib\site-packages\matplotlib\style\core.py:137[0m, in [0;36muse[1;34m(style)[0m
[0;32m    136[0m [38;5;28;01mtry[39;00m:
[1;32m--> 137[0m     style [38;5;241m=[39m [43m_rc_params_in_file[49m[43m([49m[43mstyle[49m[43m)[49m
[0;32m    138[0m [38;5;28;01mexcept[39;00m [38;5;167;01mOSError[39;00m [38;5;28;01mas[39;00m err:

File [1;32mH:\HadiSadoghiYazdi\PL\Lib\site-packages\matplotlib\__init__.py:870[0m, in [0;36m_rc_params_in_file[1;34m(fname, transform, fail_on_error)[0m
[0;32m    869[0m rc_temp [38;5;241m=[39m {}
[1;32m--> 870[0m [38;5;28;01mwith[39;00m _open_file_or_url(fname) [38;5;28;01mas[39;00m fd:
[0;32m    871[0m     [38;5;28;01mtry[39;00m:

File [1;32mC:\Program Files\Python313\Lib\contextlib.py:141[0m, in [0;36m_GeneratorContextManager.__enter__[1;34m(self)[0m
[0;32m    140[0m [38;5;28;01mtry[39;00m:
[1;32m--> 141[0m     [38;5;28;01mreturn[39;00m [38;5;28;43mnext[39;49m[43m([49m[38;5;28;43mself[39;49m[38;5;241;43m.[39;49m[43mgen[49m[43m)[49m
[0;32m    142[0m [38;5;28;01mexcept[39;00m [38;5;167;01mStopIteration[39;00m:

File [1;32mH:\HadiSadoghiYazdi\PL\Lib\site-packages\matplotlib\__init__.py:847[0m, in [0;36m_open_file_or_url[1;34m(fname)[0m
[0;32m    846[0m fname [38;5;241m=[39m os[38;5;241m.[39mpath[38;5;241m.[39mexpanduser(fname)
[1;32m--> 847[0m [38;5;28;01mwith[39;00m [38;5;28;43mopen[39;49m[43m([49m[43mfname[49m[43m,[49m[43m [49m[43mencoding[49m[38;5;241;43m=[39;49m[38;5;124;43m'[39;49m[38;5;124;43mutf-8[39;49m[38;5;124;43m'[39;49m[43m)[49m [38;5;28;01mas[39;00m f:
[0;32m    848[0m     [38;5;28;01myield[39;00m f

[1;31mFileNotFoundError[0m: [Errno 2] No such file or directory: 'seaborn'

The above exception was the direct cause of the following exception:

[1;31mOSError[0m                                   Traceback (most recent call last)
Cell [1;32mIn[1], line 12[0m
[0;32m      8[0m [38;5;28;01mfrom[39;00m [38;5;21;01msklearn[39;00m[38;5;21;01m.[39;00m[38;5;21;01mmodel_selection[39;00m [38;5;28;01mimport[39;00m train_test_split
[0;32m     10[0m X, y [38;5;241m=[39m make_blobs(n_samples [38;5;241m=[39m [38;5;241m500[39m, n_features [38;5;241m=[39m [38;5;241m2[39m, centers [38;5;241m=[39m [38;5;241m4[39m,cluster_std [38;5;241m=[39m [38;5;241m1.5[39m, random_state [38;5;241m=[39m [38;5;241m4[39m)
[1;32m---> 12[0m [43mplt[49m[38;5;241;43m.[39;49m[43mstyle[49m[38;5;241;43m.[39;49m[43muse[49m[43m([49m[38;5;124;43m'[39;49m[38;5;124;43mseaborn[39;49m[38;5;124;43m'[39;49m[43m)[49m
[0;32m     13[0m plt[38;5;241m.[39mfigure(figsize [38;5;241m=[39m ([38;5;241m10[39m,[38;5;241m10[39m))
[0;32m     14[0m plt[38;5;241m.[39mscatter(X[:,[38;5;241m0[39m], X[:,[38;5;241m1[39m], c[38;5;241m=[39my, marker[38;5;241m=[39m [38;5;124m'[39m[38;5;124m*[39m[38;5;124m'[39m,s[38;5;241m=[39m[38;5;241m100[39m,edgecolors[38;5;241m=[39m[38;5;124m'[39m[38;5;124mblack[39m[38;5;124m'[39m)

File [1;32mH:\HadiSadoghiYazdi\PL\Lib\site-packages\matplotlib\style\core.py:139[0m, in [0;36muse[1;34m(style)[0m
[0;32m    137[0m         style [38;5;241m=[39m _rc_params_in_file(style)
[0;32m    138[0m     [38;5;28;01mexcept[39;00m [38;5;167;01mOSError[39;00m [38;5;28;01mas[39;00m err:
[1;32m--> 139[0m         [38;5;28;01mraise[39;00m [38;5;167;01mOSError[39;00m(
[0;32m    140[0m             [38;5;124mf[39m[38;5;124m"[39m[38;5;132;01m{[39;00mstyle[38;5;132;01m!r}[39;00m[38;5;124m is not a valid package style, path of style [39m[38;5;124m"[39m
[0;32m    141[0m             [38;5;124mf[39m[38;5;124m"[39m[38;5;124mfile, URL of style file, or library style name (library [39m[38;5;124m"[39m
[0;32m    142[0m             [38;5;124mf[39m[38;5;124m"[39m[38;5;124mstyles are listed in `style.available`)[39m[38;5;124m"[39m) [38;5;28;01mfrom[39;00m [38;5;21;01merr[39;00m
[0;32m    143[0m filtered [38;5;241m=[39m {}
[0;32m    144[0m [38;5;28;01mfor[39;00m k [38;5;129;01min[39;00m style:  [38;5;66;03m# don't trigger RcParams.__getitem__('backend')[39;00m

[1;31mOSError[0m: 'seaborn' is not a valid package style, path of style file, URL of style file, or library style name (library styles are listed in `style.available`)

